Lỗi: [WinError 10060] A connection attempt failed because the connected party did not properly respond after a period of time, or established connection failed because connected host has failed to respond
Bot is running...
No error handlers are registered, logging exception.
Traceback (most recent call last):
  File "C:\Users\ADMIN\.virtualenvs\toolauto-0pDHeo7b\lib\site-packages\telegram\ext\_updater.py", line 750, in _network_loop_retry
    if not await do_action():
  File "C:\Users\ADMIN\.virtualenvs\toolauto-0pDHeo7b\lib\site-packages\telegram\ext\_updater.py", line 744, in do_action
    return action_cb_task.result()
  File "C:\Users\ADMIN\.virtualenvs\toolauto-0pDHeo7b\lib\site-packages\telegram\ext\_updater.py", line 371, in polling_action_cb  
    updates = await self.bot.get_updates(
  File "C:\Users\ADMIN\.virtualenvs\toolauto-0pDHeo7b\lib\site-packages\telegram\ext\_extbot.py", line 650, in get_updates
    updates = await super().get_updates(
  File "C:\Users\ADMIN\.virtualenvs\toolauto-0pDHeo7b\lib\site-packages\telegram\_bot.py", line 4480, in get_updates
    await self._post(
  File "C:\Users\ADMIN\.virtualenvs\toolauto-0pDHeo7b\lib\site-packages\telegram\_bot.py", line 619, in _post
    return await self._do_post(
  File "C:\Users\ADMIN\.virtualenvs\toolauto-0pDHeo7b\lib\site-packages\telegram\ext\_extbot.py", line 354, in _do_post
    return await super()._do_post(
  File "C:\Users\ADMIN\.virtualenvs\toolauto-0pDHeo7b\lib\site-packages\telegram\_bot.py", line 648, in _do_post
    result = await request.post(
  File "C:\Users\ADMIN\.virtualenvs\toolauto-0pDHeo7b\lib\site-packages\telegram\request\_baserequest.py", line 202, in post
    result = await self._request_wrapper(
  File "C:\Users\ADMIN\.virtualenvs\toolauto-0pDHeo7b\lib\site-packages\telegram\request\_baserequest.py", line 385, in _request_wrapper
    raise Conflict(message)
telegram.error.Conflict: Conflict: terminated by other getUpdates request; make sure that only one bot instance is running
No error handlers are registered, logging exception.
Traceback (most recent call last):
  File "C:\Users\ADMIN\.virtualenvs\toolauto-0pDHeo7b\lib\site-packages\telegram\ext\_updater.py", line 750, in _network_loop_retry
    if not await do_action():
  File "C:\Users\ADMIN\.virtualenvs\toolauto-0pDHeo7b\lib\site-packages\telegram\ext\_updater.py", line 744, in do_action
    return action_cb_task.result()
  File "C:\Users\ADMIN\.virtualenvs\toolauto-0pDHeo7b\lib\site-packages\telegram\ext\_updater.py", line 371, in polling_action_cb
    updates = await self.bot.get_updates(
  File "C:\Users\ADMIN\.virtualenvs\toolauto-0pDHeo7b\lib\site-packages\telegram\ext\_extbot.py", line 650, in get_updates
    updates = await super().get_updates(
  File "C:\Users\ADMIN\.virtualenvs\toolauto-0pDHeo7b\lib\site-packages\telegram\_bot.py", line 4480, in get_updates
    await self._post(
  File "C:\Users\ADMIN\.virtualenvs\toolauto-0pDHeo7b\lib\site-packages\telegram\_bot.py", line 619, in _post
    return await self._do_post(
  File "C:\Users\ADMIN\.virtualenvs\toolauto-0pDHeo7b\lib\site-packages\telegram\ext\_extbot.py", line 354, in _do_post
    return await super()._do_post(
  File "C:\Users\ADMIN\.virtualenvs\toolauto-0pDHeo7b\lib\site-packages\telegram\_bot.py", line 648, in _do_post
    result = await request.post(
  File "C:\Users\ADMIN\.virtualenvs\toolauto-0pDHeo7b\lib\site-packages\telegram\request\_baserequest.py", line 202, in post
    result = await self._request_wrapper(
  File "C:\Users\ADMIN\.virtualenvs\toolauto-0pDHeo7b\lib\site-packages\telegram\request\_baserequest.py", line 385, in _request_wrapper
    raise Conflict(message)
telegram.error.Conflict: Conflict: terminated by other getUpdates request; make sure that only one bot instance is running
No error handlers are registered, logging exception.
Traceback (most recent call last):
  File "C:\Users\ADMIN\.virtualenvs\toolauto-0pDHeo7b\lib\site-packages\telegram\ext\_updater.py", line 750, in _network_loop_retry
    if not await do_action():
  File "C:\Users\ADMIN\.virtualenvs\toolauto-0pDHeo7b\lib\site-packages\telegram\ext\_updater.py", line 744, in do_action
    return action_cb_task.result()
  File "C:\Users\ADMIN\.virtualenvs\toolauto-0pDHeo7b\lib\site-packages\telegram\ext\_updater.py", line 371, in polling_action_cb
    updates = await self.bot.get_updates(
  File "C:\Users\ADMIN\.virtualenvs\toolauto-0pDHeo7b\lib\site-packages\telegram\ext\_extbot.py", line 650, in get_updates
    updates = await super().get_updates(
  File "C:\Users\ADMIN\.virtualenvs\toolauto-0pDHeo7b\lib\site-packages\telegram\_bot.py", line 4480, in get_updates
    await self._post(
  File "C:\Users\ADMIN\.virtualenvs\toolauto-0pDHeo7b\lib\site-packages\telegram\_bot.py", line 619, in _post
    return await self._do_post(
  File "C:\Users\ADMIN\.virtualenvs\toolauto-0pDHeo7b\lib\site-packages\telegram\ext\_extbot.py", line 354, in _do_post
    return await super()._do_post(
  File "C:\Users\ADMIN\.virtualenvs\toolauto-0pDHeo7b\lib\site-packages\telegram\_bot.py", line 648, in _do_post
    result = await request.post(
  File "C:\Users\ADMIN\.virtualenvs\toolauto-0pDHeo7b\lib\site-packages\telegram\request\_baserequest.py", line 202, in post
    result = await self._request_wrapper(
  File "C:\Users\ADMIN\.virtualenvs\toolauto-0pDHeo7b\lib\site-packages\telegram\request\_baserequest.py", line 385, in _request_wrapper
    raise Conflict(message)
telegram.error.Conflict: Conflict: terminated by other getUpdates request; make sure that only one bot instance is running
No error handlers are registered, logging exception.
Traceback (most recent call last):
  File "C:\Users\ADMIN\.virtualenvs\toolauto-0pDHeo7b\lib\site-packages\telegram\ext\_updater.py", line 750, in _network_loop_retry
    if not await do_action():
  File "C:\Users\ADMIN\.virtualenvs\toolauto-0pDHeo7b\lib\site-packages\telegram\ext\_updater.py", line 744, in do_action
    return action_cb_task.result()
  File "C:\Users\ADMIN\.virtualenvs\toolauto-0pDHeo7b\lib\site-packages\telegram\ext\_updater.py", line 371, in polling_action_cb
    updates = await self.bot.get_updates(
  File "C:\Users\ADMIN\.virtualenvs\toolauto-0pDHeo7b\lib\site-packages\telegram\ext\_extbot.py", line 650, in get_updates
    updates = await super().get_updates(
  File "C:\Users\ADMIN\.virtualenvs\toolauto-0pDHeo7b\lib\site-packages\telegram\_bot.py", line 4480, in get_updates
    await self._post(
  File "C:\Users\ADMIN\.virtualenvs\toolauto-0pDHeo7b\lib\site-packages\telegram\_bot.py", line 619, in _post
    return await self._do_post(
  File "C:\Users\ADMIN\.virtualenvs\toolauto-0pDHeo7b\lib\site-packages\telegram\ext\_extbot.py", line 354, in _do_post
    return await super()._do_post(
  File "C:\Users\ADMIN\.virtualenvs\toolauto-0pDHeo7b\lib\site-packages\telegram\_bot.py", line 648, in _do_post
    result = await request.post(
  File "C:\Users\ADMIN\.virtualenvs\toolauto-0pDHeo7b\lib\site-packages\telegram\request\_baserequest.py", line 202, in post
    result = await self._request_wrapper(
  File "C:\Users\ADMIN\.virtualenvs\toolauto-0pDHeo7b\lib\site-packages\telegram\request\_baserequest.py", line 385, in _request_wrapper
    raise Conflict(message)
telegram.error.Conflict: Conflict: terminated by other getUpdates request; make sure that only one bot instance is running
Traceback (most recent call last):
  File "d:\bot telegram cào chứng khoán\test github\K64_chuyende2\bt1\main1.py", line 155, in <module>
    main()
  File "d:\bot telegram cào chứng khoán\test github\K64_chuyende2\bt1\main1.py", line 151, in main
    app.run_polling()
  File "C:\Users\ADMIN\.virtualenvs\toolauto-0pDHeo7b\lib\site-packages\telegram\ext\_application.py", line 868, in run_polling
    return self.__run(
  File "C:\Users\ADMIN\.virtualenvs\toolauto-0pDHeo7b\lib\site-packages\telegram\ext\_application.py", line 1088, in __run
    loop.run_until_complete(self.updater.stop())  # type: ignore[union-attr]
  File "C:\Users\ADMIN\AppData\Local\Programs\Python\Python310\lib\asyncio\base_events.py", line 636, in run_until_complete
    self.run_forever()
  File "C:\Users\ADMIN\AppData\Local\Programs\Python\Python310\lib\asyncio\windows_events.py", line 321, in run_forever
    super().run_forever()
  File "C:\Users\ADMIN\AppData\Local\Programs\Python\Python310\lib\asyncio\base_events.py", line 603, in run_forever
    self._run_once()
  File "C:\Users\ADMIN\AppData\Local\Programs\Python\Python310\lib\asyncio\base_events.py", line 1868, in _run_once
    event_list = self._selector.select(timeout)
  File "C:\Users\ADMIN\AppData\Local\Programs\Python\Python310\lib\asyncio\windows_events.py", line 439, in select
    self._poll(timeout)
  File "C:\Users\ADMIN\AppData\Local\Programs\Python\Python310\lib\asyncio\windows_events.py", line 792, in _poll
    status = _overlapped.GetQueuedCompletionStatus(self._iocp, ms)
KeyboardInterrupt